Workbook

Sheet HOW_TO_USE
A1: EMPIRE FGA | VIDEO ANALYSIS SCORING TEMPLATE | v1.0 | OBI + SII + 11 Video Metrics
A2: Companion to: Empire FGA OBI & SII Rubric Framework v1.0 | Use with: Empire_FGA_Eredivisie_2025_2026_v3.0.xlsx | March 2026
B4: THE CORE PRINCIPLE | C4: Score one metric across all matches — not all metrics in one match. This is faster, more accurate, and avoids rubric fatigue.
B6: STEP 1 | C6: Fill in PLAYER_PROFILE tab. Enter player name, position, league, season, and notes on why they were selected. Complete the MATCH_REGISTER — all 5 matches before you start scoring.
B7: STEP 2 | C7: Check the MATCH_BALANCE indicator in PLAYER_PROFILE. You need: ≥2 matches vs top-third opposition | ≥1 away match | ≥1 match where team was losing. Do not score until the balance check shows ✅ on all three.
B8: STEP 3 | C8: Choose ONE metric to score across all 5 matches. Open EVENT_LOG. Select the metric from the dropdown in column C. Watch Match 1 entirely, logging only events relevant to that metric. For each event: timestamp (MM:SS), brief description, quality score 1–10.
B9: STEP 4 | C9: Repeat for Matches 2–5 with the same metric. Then move to the next metric and repeat the entire pass. Do not skip between metrics in the same session.
B10: STEP 5 | C10: SCORES tab auto-calculates. Sub-component averages → composite scores → FGA_v3_Video_Score. Review the CONFIDENCE_FLAG column — scores with fewer than 3 events are flagged ⚠️.
B11: STEP 6 | C11: Transfer final scores to Empire_FGA_Eredivisie_2025_2026_v3.0.xlsx Tier 3 — Scout Metrics tab. Enter sub-component scores (e.g. OBI_T, OBI_S, OBI_P). The workbook calculates OBI, SII and Video_Completeness automatically.
B13: MINIMUM SAMPLE RULE | C13: 3 separate matches must show evidence of EACH sub-component before it can be scored. If a sub-component has fewer than 3 qualifying events across 5 matches: → Mark as VIDEO_PENDING in the SCORES tab, do not enter a score. → Schedule 1–2 additional matches for that specific sub-component.
B15: SESSION STRUCTURE | C15: One metric pass ≈ 45 minutes per match. Five matches × 45 min = 3h 45min per sub-metric. OBI (3 sub-metrics) + SII (3 sub-metrics) = full physical + off-ball assessment in ~22 hours. Plan 2–3 focused sessions per sub-metric. Never score while fatigued.
B17: CAMERA LIMITATION NOTE | C17: Pre-1985 footage: fixed cameras cut off far-side off-ball movement. If OBI_S or OBI_T events on the blind side cannot be observed: → Log: 'Camera: blind side — unobservable' in the Notes column. → SCORES tab will flag partial camera coverage automatically if ≥30% of events carry this note.
B19: HALO EFFECT RULE | C19: Never adjust a score because of the player's reputation. A poor decision is a poor decision for Johan Cruyff or a Belgian fourth-division midfielder. The timestamp is your evidence. The rubric is your standard. Nothing else.
B21: LARS PILOT NOTE | C21: For the 20 Malmö academy players (14–16 year olds): Lars's framework prioritises Mental Intensity, Physical Intensity, Coachability. → Mental Intensity maps to: OBI (off-ball reading), DMA (decision making), MCS → Physical Intensity maps to: SII (sprint intensity), SOA → Coachability maps to: COACH metric (separate rubric) Start with OBI and SII for all 20 players. Add DMA and COACH second pass.

Sheet PLAYER_PROFILE
A1: EMPIRE FGA | PLAYER PROFILE & MATCH REGISTER
B2: PLAYER INFORMATION
B3: Player Name | C3: Ronaldo de Assis Moreira "Ronaldinho Gaúcho" | E3: ← Enter full name as it appears in the workbook
B4: Position | C4: Attacking Midfield / Left Wing | E4: ← e.g. MF / FW / DF / GK
B5: Club (this season) | C5: Gremio FBPA
B6: League | C6: Continental — Copa Libertadores / Copa Mercosul (1998) | E6: ← e.g. Eredivisie / Allsvenskan / Malmö FF U19
B7: Season | C7: 1998
B8: Assessment Type | C8: TIER A | E8: ← TIER A (full 13 metrics) / TIER B (OBI + SII only)
B9: Analyst Name | C9: Jim Totime | E9: ← Person conducting the video assessment
B10: Date Started | C10: 46261
B11: Date Completed
B12: GPS Context | C12: Yes | E12: ← Paste relevant line from GPS_REFERENCE tab if available
B13: Selection Reason | C13: ESN Historical Pilot | E13: ← Why was this player selected? Which prospect does this support?
B16: MATCH REGISTER — Minimum 5 matches required
B17: Match # | C17: Date | D17: Home / Away | E17: Opponent | F17: Result (score) | G17: Team Winning/Losing/Drawing | H17: Opposition Tier (1=top / 3=bottom)
B18: Match 1 | C18: 35858 | D18: Home | E18: Vasco | F18: Winning | G18: 1 (Top third) | H18: RW
B19: Match 2 | C19: 36124 | D19: Away | E19: Corinthians | F19: Losing | G19: 1 (Top third) | H19: RW
B20: Match 3 | C20: 35885 | D20: Home | E20: Chivas | F20: Winning | G20: 2 (Middle third)
B21: Match 4 | C21: 35900 | D21: Away | E21: Nacional | F21: Winning | G21: 1 (Top third)
B22: Match 5 | C22: 36039 | D22: Home | E22: Universidad Católica | F22: Winning | G22: 2 (Middle third) | H22: SS
B23: Match 6 | C23: 36083 | D23: Home | E23: Santos | F23: Winning | G23: 1 (Top third)
B24: Match 7 | C24: 35892 | D24: Home | E24: América (MEX) | F24: Winning | G24: 1 (Top third)
B25: Match 8
B26: Match 9
B27: Match 10
B28: MATCH BALANCE CHECK — Must pass all 3 before scoring begins
B29: ≥2 matches vs top-third opposition | E29: =IF(COUNTIF(G18:G27,"1 (Top third)")>=2,"✅ PASS","❌ FAIL — add top-third match") -> ✅ PASS
B30: ≥1 away match | E30: =IF(COUNTIF(D18:D27,"Away")>=1,"✅ PASS","❌ FAIL — add away match") -> ✅ PASS
B31: ≥1 match where team was losing | E31: =IF(COUNTIF(F18:F27,"Losing")>=1,"✅ PASS","❌ FAIL — add match when team was losing") -> ✅ PASS
B32: Minimum 5 matches registered | E32: =IF(COUNTA(C18:C27)>=5,"✅ PASS","❌ FAIL — "&(5-COUNTA(C18:C27))&" more match(es) needed") -> ✅ PASS
B34: SCORING READINESS | E34: =IF(AND(COUNTIF(G18:G27,"1 (Top third)")>=2,COUNTIF(D18:D27,"Away")>=1,COUNTIF(F18:F27,"Losing")>=1,COUNTA(C18:C27)>=5),"✅ READY TO SCORE","❌ NOT READY — check balance above") -> ✅ READY TO SCORE

Sheet EVENT_LOG
A1: EMPIRE FGA | EVENT LOG | One metric pass at a time — Log every qualifying event with timestamp and quality score
A2: HOW TO USE: Select metric → Watch all 5 matches → Log one event per row. Quality 1–10: 10=textbook example from rubric, 1=barely qualifies as an event. Negative events (anti-indicators) score 1–4.
A3: # | B3: Match # | C3: Metric Code | D3: Timestamp MM:SS | E3: Event Description — What exactly did the player do? | F3: Quality 1–10 | G3: Event Type | H3: Camera OK? | I3: Video Clip Ref.
A4: ▶ METRIC PASS 1 — Select metric in column C and fill this pass before starting next
A5: 1 | B5: 2 | C5: CHR | D5: 78'50 | E5: Barely entered on the pitch he claim the ball and cross | F5: 9 | G5: Positive indicator | H5: Yes
A6: 2 | B6: 2 | C6: LCR | D6: 78'50 | E6: Barely entered on the pitch he claim the ball and cross | F6: 6 | G6: Positive indicator | H6: Yes
A7: 3 | B7: 2 | C7: DMA | D7: 78'50 | E7: Barely entered on the pitch he claim the ball and cross | F7: 6 | G7: Positive indicator | H7: Yes
A8: 4 | B8: 2 | C8: SII_A | D8: 82'47 | E8: High speed, create the 1-2 but can't catch the ball | F8: 8 | G8: Positive indicator | H8: Yes
A9: 5 | B9: 2 | C9: DMA | D9: 82'47 | E9: High speed, create the 1-2 but can't catch the ball | F9: 8 | G9: Positive indicator | H9: Yes
A10: 6 | B10: 2 | C10: OBI_S | D10: 82'47 | E10: High speed, create the 1-2 but can't catch the ball | F10: 8 | G10: Positive indicator | H10: Yes
A11: 7 | B11: 2 | C11: DYN | D11: 82'47 | E11: High speed, create the 1-2 but can't catch the ball | F11: 8 | G11: Positive indicator | H11: Yes
A12: 8 | B12: 2 | C12: SII_R | D12: 82'47 | E12: High speed, create the 1-2 but can't catch the ball | F12: 6 | G12: Positive indicator | H12: Yes
A13: 9 | B13: 2 | C13: SOA | D13: 90'13 | E13: Dribbling and foul submitted | F13: 8 | G13: Positive indicator | H13: Yes
A14: 10 | B14: 2 | C14: DRB | D14: 90'13 | E14: Dribbling and foul submitted | F14: 8 | G14: Positive indicator | H14: Yes
A15: 11 | B15: 2 | C15: MCS | D15: 90'49 | E15: Despite his young age, he takes the ball to kick himself the free kick but completely missed | F15: 8 | G15: Positive indicator | H15: Yes
A16: 12 | B16: 2 | C16: DMA | D16: 90'49 | E16: Despite his young age, he takes the ball to kick himself the free kick but completely missed | F16: 4 | G16: Positive indicator | H16: Yes
... A18: 14 | B18: 2 | C18: CRK | D18: 90'49 | E18: Despite his young age, he takes the ball to kick himself the free kick but completely missed | F18: 4 | G18: Positive indicator | H18: Yes
A19: 15 | B19: 3 | C19: DMA | D19: 8'52 | E19: Excellent free kick and the header of his team mate ends on the bar | F19: 9.5 | G19: Positive indicator | H19: Yes
A20: 16 | B20: 3 | C20: KEY | D20: 8'53 | E20: Excellent free kick and the header of his team mate ends on the bar | F20: 9.5 | G20: Positive indicator | H20: Yes
A21: 17 | B21: 3 | C21: LCR | D21: 8'52 | E21: Excellent free kick and the header of his team mate ends on the bar | F21: 9.5 | G21: Positive indicator | H21: Yes
A22: 18 | B22: 1 | C22: OBI_T | D22: 2'50 | E22: Wrong run timing and ball lost | F22: 5 | G22: Positive indicator | H22: Yes
A23: 19 | B23: 1 | C23: REA | D23: 2'50 | E23: Wrong run timing and ball lost | F23: 5 | G23: Positive indicator | H23: Yes
A24: ▶ METRIC PASS 2
A25: 20 | B25: 1 | C25: OBI_T | D25: 2'55 | E25: Excellent game reading and ball recovery | F25: 9 | G25: Positive indicator | H25: Yes
A26: 21 | B26: 1 | C26: INT | D26: 2'55 | E26: Excellent game reading and ball recovery | F26: 9 | G26: Positive indicator | H26: Yes
A27: 22 | B27: 1 | C27: SII_A | D27: 2'55 | E27: Excellent game reading and ball recovery | F27: 9 | G27: Positive indicator | H27: Yes
A28: 23 | B28: 1 | C28: SOA | D28: 9'32 | E28: Spectacle made, sombrero and drive the ball by header and shot but totally wide. Pure joga bonito | F28: 9 | G28: Positive indicator | H28: Yes
A29: 24 | B29: 1 | C29: DRB | D29: 9'32 | E29: Spectacle made, sombrero and drive the ball by header and shot but totally wide. Pure joga bonito | F29: 9 | G29: Positive indicator | H29: Yes
A30: 25 | B30: 1 | C30: CRK | D30: 9'32 | E30: Spectacle made, sombrero and drive the ball by header and shot but totally wide. Pure joga bonito | F30: 9 | G30: Positive indicator | H30: Yes
A31: 26 | B31: 1 | C31: STK | D31: 9'32 | E31: Spectacle made, sombrero and drive the ball by header and shot but totally wide. Pure joga bonito | F31: 9 | G31: Positive indicator | H31: Yes
A32: 27 | B32: 1 | C32: OBI_S | D32: 15'16 | E32: Not good movement to create space | F32: 6 | G32: Positive indicator | H32: Yes
A33: 28 | B33: 1 | C33: SPI | D33: 15'54 | E33: Excellent body movement to get past his opponent on the right and cross deflected by Mauro Galvão. Corner | F33: 9 | G33: Positive indicator | H33: Yes
A34: 29 | B34: 1 | C34: BDY | D34: 15'54 | E34: Excellent body movement to get past his opponent on the right and cross deflected by Mauro Galvão. Corner | F34: 9 | G34: Positive indicator | H34: Yes
A35: 30 | B35: 1 | C35: CAR | D35: 15'54 | E35: Excellent body movement to get past his opponent on the right and cross deflected by Mauro Galvão. Corner | F35: 9 | G35: Positive indicator | H35: Yes
A36: 31 | B36: 1 | C36: SII_T | D36: 15'54 | E36: Excellent body movement to get past his opponent on the right and cross deflected by Mauro Galvão. Corner | F36: 9 | G36: Positive indicator | H36: Yes
... A43: 38 | B43: 1 | C43: SOA | D43: 20'11 | E43: Very good reaction to comes first on the ball and turn around dribbling and progressive pass | F43: 9 | G43: Positive indicator | H43: Yes
A44: ▶ METRIC PASS 3
A45: 39 | B45: 1 | C45: VRP | D45: 20'11 | E45: Very good reaction to comes first on the ball and turn around dribbling and progressive pass | F45: 8 | G45: Positive indicator | H45: Yes
A46: 40 | B46: 1 | C46: DRB | D46: 20'11 | E46: Very good reaction to comes first on the ball and turn around dribbling and progressive pass | F46: 9 | G46: Positive indicator | H46: Yes
A47: 41 | B47: 1 | C47: INT | D47: 20'11 | E47: Very good reaction to comes first on the ball and turn around dribbling and progressive pass | F47: 9 | G47: Positive indicator | H47: Yes
...

Sheet SCORES
A1: EMPIRE FGA | SCORES — Auto-calculated from EVENT_LOG | Review confidence flags before transferring
A2: Player: → check PLAYER_PROFILE tab | Scores below auto-average quality ratings from EVENT_LOG. ⚠️ flag = fewer than 3 events logged (VIDEO_PENDING). Transfer to Tier 3 — Scout Metrics ONLY when confidence = ✅
B3: Player: | E3: =PLAYER_PROFILE!C3 -> Ronaldo de Assis Moreira "Ronaldinho Gaúcho"
B5: OBI — Off-Ball Intelligence
B6: Sub-Metric | C6: Weight | D6: Events Logged | E6: Events (+ve) | F6: Events (-ve) | G6: Raw Avg | H6: SCORE 0–10 | I6: Confidence | J6: Transfer Note | K6: Distinct Matches
B7: OBI_T — Run Timing | C7: 35% | D7: =COUNTIF(EVENT_LOG!$C:$C,"OBI_T") -> 8 | E7: =COUNTIFS(EVENT_LOG!$C:$C,"OBI_T",EVENT_LOG!$G:$G,"Positive indicator") -> 8 | F7: =COUNTIFS(EVENT_LOG!$C:$C,"OBI_T",EVENT_LOG!$G:$G,"Anti-indicator") -> 0 | G7: =IFERROR(AVERAGEIFS(EVENT_LOG!$F:$F,EVENT_LOG!$C:$C,"OBI_T",EVENT_LOG!$G:$G,"Positive indicator"),"—") -> 8.2857143 | H7: =IF(ISNUMBER(G7),MAX(0,MIN(10,G7)),"—") -> 8.2857143 | I7: =IF(ISNUMBER(D7),IF(K7>=3,"✅ OK","⚠️ <3 distinct matches — VIDEO_PENDING"),"—") -> ✅ OK | J7: → Tier 3 col OBI_T | K7: =SUMPRODUCT(--(COUNTIFS(EVENT_LOG!$C:$C,"OBI_T",EVENT_LOG!$B:$B,{1,2,3,4,5,6,7,8,9,10,11,12,13,14,15,16,17,18,19,20,21,22,23,24,25,26,27,28,29,30,31,32,33,34,35,36,37,38,39,40,41,42,43,44,45,46,47,48,49,50})>0)) -> 4
B8: OBI_S — Space Architecture | C8: 35% | D8: =COUNTIF(EVENT_LOG!$C:$C,"OBI_S") -> 5 | E8: =COUNTIFS(EVENT_LOG!$C:$C,"OBI_S",EVENT_LOG!$G:$G,"Positive indicator") -> 5 | F8: =COUNTIFS(EVENT_LOG!$C:$C,"OBI_S",EVENT_LOG!$G:$G,"Anti-indicator") -> 0 | G8: =IFERROR(AVERAGEIFS(EVENT_LOG!$F:$F,EVENT_LOG!$C:$C,"OBI_S",EVENT_LOG!$G:$G,"Positive indicator"),"—") -> 7.8 | H8: =IF(ISNUMBER(G8),MAX(0,MIN(10,G8)),"—") -> 7.8 | I8: =IF(ISNUMBER(D8),IF(K8>=3,"✅ OK","⚠️ <3 distinct matches — VIDEO_PENDING"),"—") -> ✅ OK | J8: → Tier 3 col OBI_S | K8: =SUMPRODUCT(--(COUNTIFS(EVENT_LOG!$C:$C,"OBI_S",EVENT_LOG!$B:$B,{1,2,3,4,5,6,7,8,9,10,11,12,13,14,15,16,17,18,19,20,21,22,23,24,25,26,27,28,29,30,31,32,33,34,35,36,37,38,39,40,41,42,43,44,45,46,47,48,49,50})>0)) -> 3
B9: OBI_P — Positional Anticipation | C9: 30% | D9: =COUNTIF(EVENT_LOG!$C:$C,"OBI_P") -> 6 | E9: =COUNTIFS(EVENT_LOG!$C:$C,"OBI_P",EVENT_LOG!$G:$G,"Positive indicator") -> 6 | F9: =COUNTIFS(EVENT_LOG!$C:$C,"OBI_P",EVENT_LOG!$G:$G,"Anti-indicator") -> 0 | G9: =IFERROR(AVERAGEIFS(EVENT_LOG!$F:$F,EVENT_LOG!$C:$C,"OBI_P",EVENT_LOG!$G:$G,"Positive indicator"),"—") -> 6.6666667 | H9: =IF(ISNUMBER(G9),MAX(0,MIN(10,G9)),"—") -> 6.6666667 | I9: =IF(ISNUMBER(D9),IF(K9>=3,"✅ OK","⚠️ <3 distinct matches — VIDEO_PENDING"),"—") -> ✅ OK | J9: → Tier 3 col OBI_P | K9: =SUMPRODUCT(--(COUNTIFS(EVENT_LOG!$C:$C,"OBI_P",EVENT_LOG!$B:$B,{1,2,3,4,5,6,7,8,9,10,11,12,13,14,15,16,17,18,19,20,21,22,23,24,25,26,27,28,29,30,31,32,33,34,35,36,37,38,39,40,41,42,43,44,45,46,47,48,49,50})>0)) -> 3
B10: OBI COMPOSITE | C10: (T×0.35)+(S×0.35)+(P×0.30) | H10: =IF(AND(ISNUMBER(H7),ISNUMBER(H8),ISNUMBER(H9)),ROUND(H7*0.35+H8*0.35+H9*0.3,2),"—") -> 7.63 | I10: =IF(AND(K7>=3,K8>=3,K9>=3),"✅ Transfer ready","⚠️ Sub-metrics pending") -> ✅ Transfer ready | J10: → Tier 3 col OBI (auto-calculates from sub-scores in workbook)
B12: SII — Sprint Intensity Index (replaces SPR_LEGACY)
B13: Sub-Metric | C13: Weight | D13: Events Logged | E13: Events (+ve) | F13: Events (-ve) | G13: Raw Avg | H13: SCORE 0–10 | I13: Confidence | J13: Transfer Note | K13: Distinct Matches
B14: SII_A — Explosive Acceleration | C14: 40% | D14: =COUNTIF(EVENT_LOG!$C:$C,"SII_A") -> 9 | E14: =COUNTIFS(EVENT_LOG!$C:$C,"SII_A",EVENT_LOG!$G:$G,"Positive indicator") -> 9 | F14: =COUNTIFS(EVENT_LOG!$C:$C,"SII_A",EVENT_LOG!$G:$G,"Anti-indicator") -> 0 | G14: =IFERROR(AVERAGEIFS(EVENT_LOG!$F:$F,EVENT_LOG!$C:$C,"SII_A",EVENT_LOG!$G:$G,"Positive indicator"),"—") -> 8.8888889 | H14: =IF(ISNUMBER(G14),MAX(0,MIN(10,G14)),"—") -> 8.8888889 | I14: =IF(ISNUMBER(D14),IF(K14>=3,"✅ OK","⚠️ <3 distinct matches — VIDEO_PENDING"),"—") -> ✅ OK | J14: → Tier 3 col SII_A | K14: =SUMPRODUCT(--(COUNTIFS(EVENT_LOG!$C:$C,"SII_A",EVENT_LOG!$B:$B,{1,2,3,4,5,6,7,8,9,10,11,12,13,14,15,16,17,18,19,20,21,22,23,24,25,26,27,28,29,30,31,32,33,34,35,36,37,38,39,40,41,42,43,44,45,46,47,48,49,50})>0)) -> 4
B15: SII_T — Top-End Speed Relative | C15: 35% | D15: =COUNTIF(EVENT_LOG!$C:$C,"SII_T") -> 6 | E15: =COUNTIFS(EVENT_LOG!$C:$C,"SII_T",EVENT_LOG!$G:$G,"Positive indicator") -> 6 | F15: =COUNTIFS(EVENT_LOG!$C:$C,"SII_T",EVENT_LOG!$G:$G,"Anti-indicator") -> 0 | G15: =IFERROR(AVERAGEIFS(EVENT_LOG!$F:$F,EVENT_LOG!$C:$C,"SII_T",EVENT_LOG!$G:$G,"Positive indicator"),"—") -> 8 | H15: =IF(ISNUMBER(G15),MAX(0,MIN(10,G15)),"—") -> 8 | I15: =IF(ISNUMBER(D15),IF(K15>=3,"✅ OK","⚠️ <3 distinct matches — VIDEO_PENDING"),"—") -> ✅ OK | J15: → Tier 3 col SII_T | K15: =SUMPRODUCT(--(COUNTIFS(EVENT_LOG!$C:$C,"SII_T",EVENT_LOG!$B:$B,{1,2,3,4,5,6,7,8,9,10,11,12,13,14,15,16,17,18,19,20,21,22,23,24,25,26,27,28,29,30,31,32,33,34,35,36,37,38,39,40,41,42,43,44,45,46,47,48,49,50})>0)) -> 3
B16: SII_R — Recovery Sprint Frequency | C16: 25% | D16: =COUNTIF(EVENT_LOG!$C:$C,"SII_R") -> 4 | E16: =COUNTIFS(EVENT_LOG!$C:$C,"SII_R",EVENT_LOG!$G:$G,"Positive indicator") -> 4 | F16: =COUNTIFS(EVENT_LOG!$C:$C,"SII_R",EVENT_LOG!$G:$G,"Anti-indicator") -> 0 | G16: =IFERROR(AVERAGEIFS(EVENT_LOG!$F:$F,EVENT_LOG!$C:$C,"SII_R",EVENT_LOG!$G:$G,"Positive indicator"),"—") -> 8 | H16: =IF(ISNUMBER(G16),MAX(0,MIN(10,G16)),"—") -> 8 | I16: =IF(ISNUMBER(D16),IF(K16>=3,"✅ OK","⚠️ <3 distinct matches — VIDEO_PENDING"),"—") -> ✅ OK | J16: → Tier 3 col SII_R | K16: =SUMPRODUCT(--(COUNTIFS(EVENT_LOG!$C:$C,"SII_R",EVENT_LOG!$B:$B,{1,2,3,4,5,6,7,8,9,10,11,12,13,14,15,16,17,18,19,20,21,22,23,24,25,26,27,28,29,30,31,32,33,34,35,36,37,38,39,40,41,42,43,44,45,46,47,48,49,50})>0)) -> 3
B17: SII COMPOSITE | C17: (A×0.40)+(T×0.35)+(R×0.25) | H17: =IF(AND(ISNUMBER(H14),ISNUMBER(H15),ISNUMBER(H16)),ROUND(H14*0.4+H15*0.35+H16*0.25,2),"—") -> 8.36 | I17: =IF(AND(K14>=3,K15>=3,K16>=3),"✅ Transfer ready","⚠️ Sub-metrics pending") -> ✅ Transfer ready | J17: → Tier 3 col SII (auto-calculates from sub-scores in workbook)
B19: REMAINING VIDEO METRICS — Full 13-metric assessment (Tier A players)
B20: Sub-Metric | C20: Weight | D20: Events Logged | E20: Events (+ve) | F20: Events (-ve) | G20: Raw Avg | H20: SCORE 0–10 | I20: Confidence | J20: Transfer Note | K20: Distinct Matches
B21: DMA — Decision Making | C21: — | D21: =COUNTIF(EVENT_LOG!$C:$C,"DMA") -> 22 | E21: =COUNTIFS(EVENT_LOG!$C:$C,"DMA",EVENT_LOG!$G:$G,"Positive indicator") -> 22 | F21: =COUNTIFS(EVENT_LOG!$C:$C,"DMA",EVENT_LOG!$G:$G,"Anti-indicator") -> 0 | G21: =IFERROR(AVERAGEIFS(EVENT_LOG!$F:$F,EVENT_LOG!$C:$C,"DMA",EVENT_LOG!$G:$G,"Positive indicator"),"—") -> 7.3 | H21: =IF(ISNUMBER(G21),MAX(0,MIN(10,G21)),"—") -> 7.3 | I21: =IF(ISNUMBER(D21),IF(K21>=3,"✅ OK","⚠️ <3 distinct matches — VIDEO_PENDING"),"—") -> ✅ OK | J21: → Tier 3 col DMA | K21: =SUMPRODUCT(--(COUNTIFS(EVENT_LOG!$C:$C,"DMA",EVENT_LOG!$B:$B,{1,2,3,4,5,6,7,8,9,10,11,12,13,14,15,16,17,18,19,20,21,22,23,24,25,26,27,28,29,30,31,32,33,34,35,36,37,38,39,40,41,42,43,44,45,46,47,48,49,50})>0)) -> 6
B22: CHR — Character | C22: — | D22: =COUNTIF(EVENT_LOG!$C:$C,"CHR") -> 8 | E22: =COUNTIFS(EVENT_LOG!$C:$C,"CHR",EVENT_LOG!$G:$G,"Positive indicator") -> 8 | F22: =COUNTIFS(EVENT_LOG!$C:$C,"CHR",EVENT_LOG!$G:$G,"Anti-indicator") -> 0 | G22: =IFERROR(AVERAGEIFS(EVENT_LOG!$F:$F,EVENT_LOG!$C:$C,"CHR",EVENT_LOG!$G:$G,"Positive indicator"),"—") -> 8.125 | H22: =IF(ISNUMBER(G22),MAX(0,MIN(10,G22)),"—") -> 8.125 | I22: =IF(ISNUMBER(D22),IF(K22>=3,"✅ OK","⚠️ <3 distinct matches — VIDEO_PENDING"),"—") -> ✅ OK | J22: → Tier 3 col CHR | K22: =SUMPRODUCT(--(COUNTIFS(EVENT_LOG!$C:$C,"CHR",EVENT_LOG!$B:$B,{1,2,3,4,5,6,7,8,9,10,11,12,13,14,15,16,17,18,19,20,21,22,23,24,25,26,27,28,29,30,31,32,33,34,35,36,37,38,39,40,41,42,43,44,45,46,47,48,49,50})>0)) -> 3
B23: MCS — Mental Competence Score | C23: — | D23: =COUNTIF(EVENT_LOG!$C:$C,"MCS") -> 5 | E23: =COUNTIFS(EVENT_LOG!$C:$C,"MCS",EVENT_LOG!$G:$G,"Positive indicator") -> 5 | F23: =COUNTIFS(EVENT_LOG!$C:$C,"MCS",EVENT_LOG!$G:$G,"Anti-indicator") -> 0 | G23: =IFERROR(AVERAGEIFS(EVENT_LOG!$F:$F,EVENT_LOG!$C:$C,"MCS",EVENT_LOG!$G:$G,"Positive indicator"),"—") -> 7.8 | H23: =IF(ISNUMBER(G23),MAX(0,MIN(10,G23)),"—") -> 7.8 | I23: =IF(ISNUMBER(D23),IF(K23>=3,"✅ OK","⚠️ <3 distinct matches — VIDEO_PENDING"),"—") -> ✅ OK | J23: → Tier 3 col MCS | K23: =SUMPRODUCT(--(COUNTIFS(EVENT_LOG!$C:$C,"MCS",EVENT_LOG!$B:$B,{1,2,3,4,5,6,7,8,9,10,11,12,13,14,15,16,17,18,19,20,21,22,23,24,25,26,27,28,29,30,31,32,33,34,35,36,37,38,39,40,41,42,43,44,45,46,47,48,49,50})>0)) -> 3
B24: SOA — Speed on Action | C24: — | D24: =COUNTIF(EVENT_LOG!$C:$C,"SOA") -> 19 | E24: =COUNTIFS(EVENT_LOG!$C:$C,"SOA",EVENT_LOG!$G:$G,"Positive indicator") -> 19 | F24: =COUNTIFS(EVENT_LOG!$C:$C,"SOA",EVENT_LOG!$G:$G,"Anti-indicator") -> 0 | G24: =IFERROR(AVERAGEIFS(EVENT_LOG!$F:$F,EVENT_LOG!$C:$C,"SOA",EVENT_LOG!$G:$G,"Positive indicator"),"—") -> 7.7777778 | H24: =IF(ISNUMBER(G24),MAX(0,MIN(10,G24)),"—") -> 7.7777778 | I24: =IF(ISNUMBER(D24),IF(K24>=3,"✅ OK","⚠️ <3 distinct matches — VIDEO_PENDING"),"—") -> ✅ OK | J24: → Tier 3 col SOA | K24: =SUMPRODUCT(--(COUNTIFS(EVENT_LOG!$C:$C,"SOA",EVENT_LOG!$B:$B,{1,2,3,4,5,6,7,8,9,10,11,12,13,14,15,16,17,18,19,20,21,22,23,24,25,26,27,28,29,30,31,32,33,34,35,36,37,38,39,40,41,42,43,44,45,46,47,48,49,50})>0)) -> 4
B25: SPI — Spatial Performance Index | C25: — | D25: =COUNTIF(EVENT_LOG!$C:$C,"SPI") -> 4 | E25: =COUNTIFS(EVENT_LOG!$C:$C,"SPI",EVENT_LOG!$G:$G,"Positive indicator") -> 4 | F25: =COUNTIFS(EVENT_LOG!$C:$C,"SPI",EVENT_LOG!$G:$G,"Anti-indicator") -> 0 | G25: =IFERROR(AVERAGEIFS(EVENT_LOG!$F:$F,EVENT_LOG!$C:$C,"SPI",EVENT_LOG!$G:$G,"Positive indicator"),"—") -> 8.5 | H25: =IF(ISNUMBER(G25),MAX(0,MIN(10,G25)),"—") -> 8.5 | I25: =IF(ISNUMBER(D25),IF(K25>=3,"✅ OK","⚠️ <3 distinct matches — VIDEO_PENDING"),"—") -> ✅ OK | J25: → Tier 3 col SPI | K25: =SUMPRODUCT(--(COUNTIFS(EVENT_LOG!$C:$C,"SPI",EVENT_LOG!$B:$B,{1,2,3,4,5,6,7,8,9,10,11,12,13,14,15,16,17,18,19,20,21,22,23,24,25,26,27,28,29,30,31,32,33,34,35,36,37,38,39,40,41,42,43,44,45,46,47,48,49,50})>0)) -> 3
B26: CLM — Calmness | C26: — | D26: =COUNTIF(EVENT_LOG!$C:$C,"CLM") -> 3 | E26: =COUNTIFS(EVENT_LOG!$C:$C,"CLM",EVENT_LOG!$G:$G,"Positive indicator") -> 3 | F26: =COUNTIFS(EVENT_LOG!$C:$C,"CLM",EVENT_LOG!$G:$G,"Anti-indicator") -> 0 | G26: =IFERROR(AVERAGEIFS(EVENT_LOG!$F:$F,EVENT_LOG!$C:$C,"CLM",EVENT_LOG!$G:$G,"Positive indicator"),"—") -> 7 | H26: =IF(ISNUMBER(G26),MAX(0,MIN(10,G26)),"—") -> 7 | I26: =IF(ISNUMBER(D26),IF(K26>=3,"✅ OK","⚠️ <3 distinct matches — VIDEO_PENDING"),"—") -> ✅ OK | J26: → Tier 3 col CLM | K26: =SUMPRODUCT(--(COUNTIFS(EVENT_LOG!$C:$C,"CLM",EVENT_LOG!$B:$B,{1,2,3,4,5,6,7,8,9,10,11,12,13,14,15,16,17,18,19,20,21,22,23,24,25,26,27,28,29,30,31,32,33,34,35,36,37,38,39,40,41,42,43,44,45,46,47,48,49,50})>0)) -> 3
B27: CRS — Clutch Response Score | C27: — | D27: =COUNTIF(EVENT_LOG!$C:$C,"CRS") -> 6 | E27: =COUNTIFS(EVENT_LOG!$C:$C,"CRS",EVENT_LOG!$G:$G,"Positive indicator") -> 6 | F27: =COUNTIFS(EVENT_LOG!$C:$C,"CRS",EVENT_LOG!$G:$G,"Anti-indicator") -> 0 | G27: =IFERROR(AVERAGEIFS(EVENT_LOG!$F:$F,EVENT_LOG!$C:$C,"CRS",EVENT_LOG!$G:$G,"Positive indicator"),"—") -> 9 | H27: =IF(ISNUMBER(G27),MAX(0,MIN(10,G27)),"—") -> 9 | I27: =IF(ISNUMBER(D27),IF(K27>=3,"✅ OK","⚠️ <3 distinct matches — VIDEO_PENDING"),"—") -> ✅ OK | J27: → Tier 3 col CRS | K27: =SUMPRODUCT(--(COUNTIFS(EVENT_LOG!$C:$C,"CRS",EVENT_LOG!$B:$B,{1,2,3,4,5,6,7,8,9,10,11,12,13,14,15,16,17,18,19,20,21,22,23,24,25,26,27,28,29,30,31,32,33,34,35,36,37,38,39,40,41,42,43,44,45,46,47,48,49,50})>0)) -> 3
B28: OMS — Omschakeling / Transition | C28: — | D28: =COUNTIF(EVENT_LOG!$C:$C,"OMS") -> 4 | E28: =COUNTIFS(EVENT_LOG!$C:$C,"OMS",EVENT_LOG!$G:$G,"Positive indicator") -> 4 | F28: =COUNTIFS(EVENT_LOG!$C:$C,"OMS",EVENT_LOG!$G:$G,"Anti-indicator") -> 0 | G28: =IFERROR(AVERAGEIFS(EVENT_LOG!$F:$F,EVENT_LOG!$C:$C,"OMS",EVENT_LOG!$G:$G,"Positive indicator"),"—") -> 8.3333333 | H28: =IF(ISNUMBER(G28),MAX(0,MIN(10,G28)),"—") -> 8.3333333 | I28: =IF(ISNUMBER(D28),IF(K28>=3,"✅ OK","⚠️ <3 distinct matches — VIDEO_PENDING"),"—") -> ✅ OK | J28: → Tier 3 col OMS | K28: =SUMPRODUCT(--(COUNTIFS(EVENT_LOG!$C:$C,"OMS",EVENT_LOG!$B:$B,{1,2,3,4,5,6,7,8,9,10,11,12,13,14,15,16,17,18,19,20,21,22,23,24,25,26,27,28,29,30,31,32,33,34,35,36,37,38,39,40,41,42,43,44,45,46,47,48,49,50})>0)) -> 3
B29: DYN — Dynamism | C29: — | D29: =COUNTIF(EVENT_LOG!$C:$C,"DYN") -> 6 | E29: =COUNTIFS(EVENT_LOG!$C:$C,"DYN",EVENT_LOG!$G:$G,"Positive indicator") -> 6 | F29: =COUNTIFS(EVENT_LOG!$C:$C,"DYN",EVENT_LOG!$G:$G,"Anti-indicator") -> 0 | G29: =IFERROR(AVERAGEIFS(EVENT_LOG!$F:$F,EVENT_LOG!$C:$C,"DYN",EVENT_LOG!$G:$G,"Positive indicator"),"—") -> 8.5 | H29: =IF(ISNUMBER(G29),MAX(0,MIN(10,G29)),"—") -> 8.5 | I29: =IF(ISNUMBER(D29),IF(K29>=3,"✅ OK","⚠️ <3 distinct matches — VIDEO_PENDING"),"—") -> ✅ OK | J29: → Tier 3 col DYN | K29: =SUMPRODUCT(--(COUNTIFS(EVENT_LOG!$C:$C,"DYN",EVENT_LOG!$B:$B,{1,2,3,4,5,6,7,8,9,10,11,12,13,14,15,16,17,18,19,20,21,22,23,24,25,26,27,28,29,30,31,32,33,34,35,36,37,38,39,40,41,42,43,44,45,46,47,48,49,50})>0)) -> 4
B30: CRK — Creative Risk Taking | C30: — | D30: =COUNTIF(EVENT_LOG!$C:$C,"CRK") -> 9 | E30: =COUNTIFS(EVENT_LOG!$C:$C,"CRK",EVENT_LOG!$G:$G,"Positive indicator") -> 9 | F30: =COUNTIFS(EVENT_LOG!$C:$C,"CRK",EVENT_LOG!$G:$G,"Anti-indicator") -> 0 | G30: =IFERROR(AVERAGEIFS(EVENT_LOG!$F:$F,EVENT_LOG!$C:$C,"CRK",EVENT_LOG!$G:$G,"Positive indicator"),"—") -> 7.8888889 | H30: =IF(ISNUMBER(G30),MAX(0,MIN(10,G30)),"—") -> 7.8888889 | I30: =IF(ISNUMBER(D30),IF(K30>=3,"✅ OK","⚠️ <3 distinct matches — VIDEO_PENDING"),"—") -> ✅ OK | J30: → Tier 3 col CRK | K30: =SUMPRODUCT(--(COUNTIFS(EVENT_LOG!$C:$C,"CRK",EVENT_LOG!$B:$B,{1,2,3,4,5,6,7,8,9,10,11,12,13,14,15,16,17,18,19,20,21,22,23,24,25,26,27,28,29,30,31,32,33,34,35,36,37,38,39,40,41,42,43,44,45,46,47,48,49,50})>0)) -> 4
B32: VIDEO COMPLETENESS (of 12 core metrics: OBI composite + SII composite + 10 named subs) | H32: =IF(AND(K7>=3,K8>=3,K9>=3),1,0)+IF(AND(K14>=3,K15>=3,K16>=3),1,0)+IF(K21>=3,1,0)+IF(K22>=3,1,0)+IF(K23>=3,1,0)+IF(K24>=3,1,0)+IF(K25>=3,1,0)+IF(K26>=3,1,0)+IF(K27>=3,1,0)+IF(K28>=3,1,0)+IF(K29>=3,1,0)+IF(K30>=3,1,0) -> 12 | I32: =IF(H32>=12,"✅ 12/12 — FULLY GRADED",IF(H32>=7,"✅ Threshold met — FGA_v3_Final will activate","⚠️ "&(12-H32)&" more metric(s) needed for 12/12")) -> ✅ 12/12 — FULLY GRADED
B34: PHILOSOPHY-FIT PRIORITY METRICS — 9 new (Aug 2026), required by the philosophy-fit formulas
B35: Sub-Metric | C35: Weight | D35: Events Logged | E35: Events (+ve) | F35: Events (-ve) | G35: Raw Avg | H35: SCORE 0–10 | I35: Confidence
B36: KEY — Key Passes | C36: — | D36: =COUNTIF(EVENT_LOG!$C:$C,"KEY") -> 6 | E36: =COUNTIFS(EVENT_LOG!$C:$C,"KEY",EVENT_LOG!$G:$G,"Positive indicator") -> 6 | F36: =COUNTIFS(EVENT_LOG!$C:$C,"KEY",EVENT_LOG!$G:$G,"Anti-indicator") -> 0 | G36: =IFERROR(AVERAGEIFS(EVENT_LOG!$F:$F,EVENT_LOG!$C:$C,"KEY",EVENT_LOG!$G:$G,"Positive indicator"),"—") -> 8.4 | H36: =IF(ISNUMBER(G36),MAX(0,MIN(10,G36)),"—") -> 8.4 | I36: =IF(ISNUMBER(D36),IF(D36>=3,"✅ OK — event count only, not match-spread checked","⚠️ <3 events — VIDEO_PENDING"),"—") -> ✅ OK — event count only, not match-spread checked
B37: STK — Shot Technique | C37: — | D37: =COUNTIF(EVENT_LOG!$C:$C,"STK") -> 11 | E37: =COUNTIFS(EVENT_LOG!$C:$C,"STK",EVENT_LOG!$G:$G,"Positive indicator") -> 11 | F37: =COUNTIFS(EVENT_LOG!$C:$C,"STK",EVENT_LOG!$G:$G,"Anti-indicator") -> 0 | G37: =IFERROR(AVERAGEIFS(EVENT_LOG!$F:$F,EVENT_LOG!$C:$C,"STK",EVENT_LOG!$G:$G,"Positive indicator"),"—") -> 7.1 | H37: =IF(ISNUMBER(G37),MAX(0,MIN(10,G37)),"—") -> 7.1 | I37: =IF(ISNUMBER(D37),IF(D37>=3,"✅ OK — event count only, not match-spread checked","⚠️ <3 events — VIDEO_PENDING"),"—") -> ✅ OK — event count only, not match-spread checked
B38: LGP — Long Pass Precision | C38: — | D38: =COUNTIF(EVENT_LOG!$C:$C,"LGP") -> 6 | E38: =COUNTIFS(EVENT_LOG!$C:$C,"LGP",EVENT_LOG!$G:$G,"Positive indicator") -> 6 | F38: =COUNTIFS(EVENT_LOG!$C:$C,"LGP",EVENT_LOG!$G:$G,"Anti-indicator") -> 0 | G38: =IFERROR(AVERAGEIFS(EVENT_LOG!$F:$F,EVENT_LOG!$C:$C,"LGP",EVENT_LOG!$G:$G,"Positive indicator"),"—") -> 8.5 | H38: =IF(ISNUMBER(G38),MAX(0,MIN(10,G38)),"—") -> 8.5 | I38: =IF(ISNUMBER(D38),IF(D38>=3,"✅ OK — event count only, not match-spread checked","⚠️ <3 events — VIDEO_PENDING"),"—") -> ✅ OK — event count only, not match-spread checked
B39: VRP — Vertical Pass | C39: — | D39: =COUNTIF(EVENT_LOG!$C:$C,"VRP") -> 7 | E39: =COUNTIFS(EVENT_LOG!$C:$C,"VRP",EVENT_LOG!$G:$G,"Positive indicator") -> 7 | F39: =COUNTIFS(EVENT_LOG!$C:$C,"VRP",EVENT_LOG!$G:$G,"Anti-indicator") -> 0 | G39: =IFERROR(AVERAGEIFS(EVENT_LOG!$F:$F,EVENT_LOG!$C:$C,"VRP",EVENT_LOG!$G:$G,"Positive indicator"),"—") -> 8.3333333 | H39: =IF(ISNUMBER(G39),MAX(0,MIN(10,G39)),"—") -> 8.3333333 | I39: =IF(ISNUMBER(D39),IF(D39>=3,"✅ OK — event count only, not match-spread checked","⚠️ <3 events — VIDEO_PENDING"),"—") -> ✅ OK — event count only, not match-spread checked
B40: HZP — Horizontal Pass | C40: — | D40: =COUNTIF(EVENT_LOG!$C:$C,"HZP") -> 3 | E40: =COUNTIFS(EVENT_LOG!$C:$C,"HZP",EVENT_LOG!$G:$G,"Positive indicator") -> 3 | F40: =COUNTIFS(EVENT_LOG!$C:$C,"HZP",EVENT_LOG!$G:$G,"Anti-indicator") -> 0 | G40: =IFERROR(AVERAGEIFS(EVENT_LOG!$F:$F,EVENT_LOG!$C:$C,"HZP",EVENT_LOG!$G:$G,"Positive indicator"),"—") -> 7.6666667 | H40: =IF(ISNUMBER(G40),MAX(0,MIN(10,G40)),"—") -> 7.6666667 | I40: =IF(ISNUMBER(D40),IF(D40>=3,"✅ OK — event count only, not match-spread checked","⚠️ <3 events — VIDEO_PENDING"),"—") -> ✅ OK — event count only, not match-spread checked
B41: DRB — Dribbling Success Rate | C41: — | D41: =COUNTIF(EVENT_LOG!$C:$C,"DRB") -> 20 | E41: =COUNTIFS(EVENT_LOG!$C:$C,"DRB",EVENT_LOG!$G:$G,"Positive indicator") -> 20 | F41: =COUNTIFS(EVENT_LOG!$C:$C,"DRB",EVENT_LOG!$G:$G,"Anti-indicator") -> 0 | G41: =IFERROR(AVERAGEIFS(EVENT_LOG!$F:$F,EVENT_LOG!$C:$C,"DRB",EVENT_LOG!$G:$G,"Positive indicator"),"—") -> 7.4210526 | H41: =IF(ISNUMBER(G41),MAX(0,MIN(10,G41)),"—") -> 7.4210526 | I41: =IF(ISNUMBER(D41),IF(D41>=3,"✅ OK — event count only, not match-spread checked","⚠️ <3 events — VIDEO_PENDING"),"—") -> ✅ OK — event count only, not match-spread checked
B42: CAR — Ball Carries | C42: — | D42: =COUNTIF(EVENT_LOG!$C:$C,"CAR") -> 10 | E42: =COUNTIFS(EVENT_LOG!$C:$C,"CAR",EVENT_LOG!$G:$G,"Positive indicator") -> 10 | F42: =COUNTIFS(EVENT_LOG!$C:$C,"CAR",EVENT_LOG!$G:$G,"Anti-indicator") -> 0 | G42: =IFERROR(AVERAGEIFS(EVENT_LOG!$F:$F,EVENT_LOG!$C:$C,"CAR",EVENT_LOG!$G:$G,"Positive indicator"),"—") -> 7.9 | H42: =IF(ISNUMBER(G42),MAX(0,MIN(10,G42)),"—") -> 7.9 | I42: =IF(ISNUMBER(D42),IF(D42>=3,"✅ OK — event count only, not match-spread checked","⚠️ <3 events — VIDEO_PENDING"),"—") -> ✅ OK — event count only, not match-spread checked
B43: INT — Interceptions | C43: — | D43: =COUNTIF(EVENT_LOG!$C:$C,"INT") -> 8 | E43: =COUNTIFS(EVENT_LOG!$C:$C,"INT",EVENT_LOG!$G:$G,"Positive indicator") -> 8 | F43: =COUNTIFS(EVENT_LOG!$C:$C,"INT",EVENT_LOG!$G:$G,"Anti-indicator") -> 0 | G43: =IFERROR(AVERAGEIFS(EVENT_LOG!$F:$F,EVENT_LOG!$C:$C,"INT",EVENT_LOG!$G:$G,"Positive indicator"),"—") -> 7.125 | H43: =IF(ISNUMBER(G43),MAX(0,MIN(10,G43)),"—") -> 7.125 | I43: =IF(ISNUMBER(D43),IF(D43>=3,"✅ OK — event count only, not match-spread checked","⚠️ <3 events — VIDEO_PENDING"),"—") -> ✅ OK — event count only, not match-spread checked
B44: TAC — Tackling | C44: — | D44: =COUNTIF(EVENT_LOG!$C:$C,"TAC") -> 3 | E44: =COUNTIFS(EVENT_LOG!$C:$C,"TAC",EVENT_LOG!$G:$G,"Positive indicator") -> 3 | F44: =COUNTIFS(EVENT_LOG!$C:$C,"TAC",EVENT_LOG!$G:$G,"Anti-indicator") -> 0 | G44: =IFERROR(AVERAGEIFS(EVENT_LOG!$F:$F,EVENT_LOG!$C:$C,"TAC",EVENT_LOG!$G:$G,"Positive indicator"),"—") -> 5.6666667 | H44: =IF(ISNUMBER(G44),MAX(0,MIN(10,G44)),"—") -> 5.6666667 | I44: =IF(ISNUMBER(D44),IF(D44>=3,"✅ OK — event count only, not match-spread checked","⚠️ <3 events — VIDEO_PENDING"),"—") -> ✅ OK — event count only, not match-spread checked
B45: ADDITIONAL FOUNDATION METRICS — 5 new (Aug 2026), Section 1 codes previously missing from the dropdown
...

Sheet RUBRIC_QUICK_REF
A1: EMPIRE FGA | RUBRIC QUICK REFERENCE — Full rubrics in: Empire_FGA_OBI_SII_Rubric_Framework_v1.0.docx | This sheet: condensed scoring anchors for field use
B2: Code | C2: Metric | D2: Score 8–10 (Elite indicator) | E2: Score 4–5 (Average indicator) | F2: Anti-indicators (score 1–3)
B3: OBI — Off-Ball Intelligence
B4: OBI_S | C4: Space Architecture | D4: Run creates measurable space for teammates even without personal reception. ≥2 such runs per half. | E4: Run creates passing lane but primarily benefits the player themselves. | F4: No evident effect on defensive shape. Player moves for themselves only.
B5: OBI_P | C5: Positional Anticipation | D5: Already in dangerous position 2+ seconds before ball arrives. Looks unhurried, never scrambling. | E5: Arrives in position as ball arrives. Correct area, correct moment — but not ahead of play. | F5: Late to position consistently. Receives in non-threatening area. Reacts rather than anticipates.
B6: SII — Sprint Intensity Index
B7: SII_T | C7: Top-End Speed Relative | D7: Visibly reaches higher speed than all opponents in same frame. Gap grows in open space. | E7: Matches pace with opponents. Neither clearly faster nor slower than average. | F7: Regularly matched or beaten at top end. Opponents deliberately exploit this in transitions.
B8: SII_R | C8: Recovery Sprint Frequency | D8: ≥5 full recovery sprints per half. Systematic — every transition triggers a sprint. | E8: 1–2 recovery sprints per half. Selective — sprints when high-value opportunity. | F8: Near-zero recovery sprints. Jogs or walks in transition. Opponents exploit this repeatedly.
B9: Remaining Video Metrics
B10: CHR | C10: Character | D10: Responds positively to adversity. Body language strong after errors. Organises teammates. | E10: Neither inspires nor deflates teammates. Neutral presence after difficulty. | F10: Visible negative reaction to errors. Gestures/body language affect teammates negatively.
B11: MCS | C11: Mental Competence Score | D11: Maintains performance level in high-stakes moments. No performance drop under pressure. | E11: Slight performance drop under pressure but recovers. Not a liability. | F11: Significant visible deterioration under pressure. Avoids ball in difficult moments.
B12: SOA | C12: Speed on Action | D12: First touch and subsequent action within 0.5 sec of receiving. Always ahead of opponents. | E12: 1-2 second response. Functional but predictable. | F12: Slow first touch regularly enables opponents to close. Often bypassed in transitions.
B13: SPI | C13: Spatial Performance Index | D13: Consistently occupies spaces between defensive lines. Creates 2v1 situations through positioning. | E13: Finds pockets of space but does not create overloads systematically. | F13: Positional choices predictable. Opponents pre-position to cover. Creates no spatial advantage.
B14: CLM | C14: Calmness | D14: Performance unaffected by crowd noise, fouls, scoreline, referee decisions. | E14: Occasional visible frustration but recovers quickly. Does not affect performance. | F14: Regular loss of composure. Retaliates to fouls. Performance drops after referee decisions.
B15: CRS | C15: Clutch Response Score | D15: Performance measurably improves in final 10 mins or decisive moments. Steps up visibly. | E15: Performance consistent — neither rises nor falls in clutch moments. | F15: Visible performance deterioration in decisive moments. Avoids responsibility.
B16: OMS | C16: Transition (Omschakeling) | D16: First 3 steps in attack-to-defence or defence-to-attack transition within 1 second of possession change. | E16: Transitions within 2-3 seconds. Functional but gives opponents time to organise. | F16: Slow to recognise possession change. Regularly caught out of position in transitions.
B17: DYN | C17: Dynamism | D17: Occupies ≥3 different positional zones per match effectively. Tactical switching is intentional. | E17: Plays primarily in 1-2 zones. Some flexibility but primarily positional. | F17: Rigid positioning. Rarely leaves designated zone. Opponents can plan around their static location.
B18: CRK | C18: Creative Risk Taking | D18: Attempts innovative solutions to defensive problems. ≥2 per match. Risk is calculated not reckless. | E18: Occasional creative attempt but defaults to safe option when pressed. | F18: Always chooses safe option. No creative attempts. Predictable under pressure.

Sheet PUNCH_LIST
A1: PUNCH LIST — Log issues during assessment. Fix on Friday only. Never interrupt a scoring session to fix.
A2: # | B2: Player | C2: Metric | D2: Issue / What Broke | E2: Proposed Fix | F2: Priority
A3: 1
A4: 2
A5: 3
A6: 4
A7: 5
A8: 6
A9: 7
A10: 8
A11: 9
A12: 10
A13: 11
A14: 12
... A27: 25
